2018-03-01 22:37:05,243 INFO: GUI: Generación de Universos de Interventoría
2018-03-01 22:37:05,244 INFO: Getting data from db
2018-03-01 22:37:05,389 INFO: File db/data/reclamos.csv loaded
2018-03-01 22:37:05,945 INFO: File db/data/anomalect.csv loaded
2018-03-01 22:37:06,214 INFO: File db/data/anomafact.csv loaded
2018-03-01 22:37:06,214 INFO: Data wrangling
2018-03-01 22:37:06,296 INFO: unique NIS filter
2018-03-01 22:37:06,302 INFO: Reclamos filter applied
2018-03-01 22:37:06,326 INFO: Field ORIGEN processed
2018-03-01 22:37:06,327 INFO: Field DESCRIPCION added
2018-03-01 22:37:06,330 INFO: Field PROCESO processed
2018-03-01 22:37:06,333 INFO: Field PENULTIMA_LECTURA added
2018-03-01 22:37:06,334 INFO: Field TIPOEQUIPO added
2018-03-01 22:37:07,692 INFO: Added LAT, LON and DELEGACION fields
2018-03-01 22:37:07,694 INFO: Cabeceras filter
2018-03-01 22:37:07,696 INFO: unique NIF filter
2018-03-01 22:37:07,705 INFO: Field ASOCIADO_COMERCIAL processed
2018-03-01 22:37:07,707 ERROR: unhashable type: 'list'
Traceback (most recent call last):
  File "main.py", line 20, in <module>
    data = gui.data_wrangling(data, cfg)
  File "/Users/jonate/Google Drive/Projects/crowis/gui/gui.py", line 108, in data_wrangling
    data = data[[cfg.column_order]]
  File "/Users/jonate/anaconda/envs/py3/lib/python3.6/site-packages/pandas/core/frame.py", line 1958, in __getitem__
    return self._getitem_array(key)
  File "/Users/jonate/anaconda/envs/py3/lib/python3.6/site-packages/pandas/core/frame.py", line 2002, in _getitem_array
    indexer = self.loc._convert_to_indexer(key, axis=1)
  File "/Users/jonate/anaconda/envs/py3/lib/python3.6/site-packages/pandas/core/indexing.py", line 1219, in _convert_to_indexer
    indexer = check = labels.get_indexer(objarr)
  File "/Users/jonate/anaconda/envs/py3/lib/python3.6/site-packages/pandas/core/indexes/base.py", line 2598, in get_indexer
    indexer = self._engine.get_indexer(target._values)
  File "pandas/_libs/index.pyx", line 306, in pandas._libs.index.IndexEngine.get_indexer (pandas/_libs/index.c:7518)
  File "pandas/_libs/hashtable_class_helper.pxi", line 1262, in pandas._libs.hashtable.PyObjectHashTable.lookup (pandas/_libs/hashtable.c:21233)
TypeError: unhashable type: 'list'
